Workbook

Sheet G-1调查
B1: =[1]目录!A1 -> 上海城乡资产评估有限责任公司
B2: =[1]目录!A2 -> SHANGHAI URBAN & RURAL ASSETS APPRAISAL CO.,LTD
B3: 评估业务基本事项调查表
H4: 索引号：G-1
B5: 项目名称 | D5: =[1]基本信息!G6 -> 上海A公司拟股权转让涉及的上海B公司股东全部权益
B6: 委托人 | D6: =[1]基本信息!C8 -> 上海A公司 | E6: 联系人 | F6: =[1]基本信息!C39 -> 小王 | G6: 电话 | H6: =[1]基本信息!E39 -> 6462222
B7: 被评估单位 | C7: 名称 | D7: =[1]基本信息!C9 -> 上海B公司 | E7: 地址 | F7: =[1]基本信息!E40 -> 天目中路88888
C8: 法定代表人 | D8: =[1]基本信息!C41 -> 小巧 | E8: 企业性质 | F8: =[1]基本信息!E41 -> 国有
C9: 注册资金 | D9: =[1]基本信息!C40 -> 500 | E9: 联系人 | F9: =[1]基本信息!C42 -> 小欧 | G9: 电话 | H9: =[1]基本信息!E42 -> 692414545
C10: 经营范围 | D10: =[1]基本信息!C43 -> ************************
B11: 其他报告使用人 | D11: =[1]基本信息!B44 -> 无
B12: 委托人、被评估 单位、其他报告 使用人的关系 | D12: =[1]基本信息!B45 -> 股东
B13: 项目涉及的经济 行为的审批情况 | D13: =IF([1]基本信息!B48="是","备案或核准","") -> 备案或核准
B14: 委托人及相关当事人工作配合和协助等需要明确的重要事项 | D14: =[1]基本信息!B46 -> 暂无
B15: 评估目的 | D15: =[1]档案总览!B8 -> 股权转让
B16: 评估对象和 评估范围 | D16: ="评估对象是"&[1]基本信息!C5&","&"评估范围是"&[1]基本信息!C6 -> 评估对象是股东全部权益,评估范围是全部资产和全部负债
B17: 主要资产状况 | D17: 流动资产、流动负债，长期资产、长期负债
B18: 价值类型 | D18: =[1]基本信息!C7 -> 市场价值 | E18: 评估基准日 | F18: =[1]档案总览!B10 -> 2021/4/31
B19: 评估假设和 限制条件 | D19: =[1]基本信息!B47 -> 无特殊
B20: 评估报告的使用范围、提交时间和方式 | D20: 详见资产评估委托合同
B21: 评估服务费总额、 支付时间和方式 | E21: =[1]基本信息!C37 -> 10 | F21: 万元
B22: 洽谈人： | E22: 审批人： | G22: 日期： | H22: =[1]基本信息!D13 -> 44256
B23: 填表人：

Sheet G-2风险
B1: =[1]目录!A1 -> 上海城乡资产评估有限责任公司
B2: =[1]目录!A2 -> SHANGHAI URBAN & RURAL ASSETS APPRAISAL CO.,LTD
B3: 评估项目综合评价表
F4: 索引号：G-2
B5: 调查内容 | D5: 情况
B6: 一、对委托人综合评价
B7: 1、委托评估目的是否明确？是否存在风险？ | D7: 明确
B8: 2、委托人对时间要求是否紧迫？ | D8: 否
B9: 3、委托人对估值是否有特殊要求？或估值预期是否合理？ | D9: 无特殊要求
B10: 4、委托人与被评估单位的关系如何？ | D10: 正常
B11: 5、委托人有无非诚信记录？ | D11: 无
B12: 6、委托人及主要负责人社会地位如何？ | D12: 一般
B14: 二、对被评估单位综合评价
B15: 1、相关人员对评估工作是否配合？ | D15: 是
B16: 2、被评估单位是否面临财务危机？（如到期债务不能偿还或抵（质）押资产可能被处置？） | D16: 否
B17: 3、被评估单位的产权是否明晰？ | D17: 是
B18: 4、被评估单位所处行业环境是否稳定？ | D18: 是
B19: 5、被评估单位内部组织机构是否稳定？ | D19: 是
B20: 6、被评估单位内部管理和控制制度是否健全、有效？ | D20: 是
B21: 7、被评估单位基础资料档案管理是否健全？ | D21: 是
B22: 8、被评估单位财务状况是否稳定？ | D22: 是
B23: 9、被评估单位及主要负责人社会地位如何？ | D23: 一般
B25: 三、对评估对象的综合评价
B26: 1、待估资产法律权属资料是否完整、清晰？ | D26: 是
B27: 2、有无特殊而本机构没有评估经验的资产？ | D27: 无
B28: 3、有无抵押、质押、诉讼、抵债等资产的安全与完整保证程度低的资产？是否存在法律纠纷？
B30: 四、对本机构及评估人员的综合评价
B31: 1、是否具备承接该项目的资质要求？是否存在利害关系？ | D31: 是，否
B32: 2、承接该项目是否影响本机构的独立性？是否分别接受利益双方的委托？ | D32: 否
B33: 3、评估项目组成人员是否具备承接该项目的能力？是否具备与评估业务相关的专业知识及评估经验？ | D33: 是
B34: 4、拟承接该项目的评估专业人员及其他本机构评估人员是否符合独立性的要求？ | D34: 是
B35: 5、拟聘请的专家或工作人员是否符合独立性的要求？是否具备相应的专业特长、资格等能力？ | D35: 无
B37: 五、评估报告使用对项目风险的影响
B38: 1、是否需公诸于公开媒体？是否已明确报告使用人？ | D38: 已明确
B39: 2、评估报告是否可能被其他文件、资料引用？ | D39: 暂无
B40: 3、评估报告是否提交国资监管部门备案或核准？ | D40: =[1]基本信息!B48 -> 是
B41: 4、是否存在两个或两个以上利益对立的评估报告使用人？ | D41: 否
B42: 结论： 风险水平 很低 低 一般 √ 较高 很高
B43: 主要评估风险、风险可控情况及能够采取的主要措施：
B45: 是否接受委托： 是√否 洽谈人签字： | E45: 日期： | F45: =[1]基本信息!D14 -> 44257
...

Sheet 独立性调查G-28
A1: 项目组成员独立性调查问卷
A2: =[1]基本信息!B9&[1]基本信息!L5&[1]基本信息!C9 -> 被评估单位：上海B公司 | C2: 索引号 | E2: G28
A3: =[1]基本信息!B3&[1]基本信息!L5&[1]基本信息!C3 -> 评估基准日：2021/4/31 | C3: 项目负责人： | E3: =[1]基本信息!C28 -> 小包
B4: 调查项目 | C4: 是 | D4: 否 | E4: 不适用
A5: 1 | B5: 您是否清楚所在公司质量控制制度及独立性制度中有关独立性的规定？ | C5: √
A6: 2 | B6: 您及您亲属是否在委托人或相关当事方中拥有直接经济利益或重大间接利益？是否存在提供直接影响该项业务对象的其他服务？ | D6: √
A7: 3 | B7: 您及您亲属是否拥有委托人或相关当事方的股权、债权、有价证券、债务，或者存在担保等可能影响独立性的经济利益关系？ | D7: √
A8: 4 | B8: 您及您亲属是否与委托人或相关当事方从事的业务之间可能存在的其他利益输送或者利益冲突关系情形？ | D8: √
A9: 5 | B9: 您及您亲属是否从委托人或相关当事方取得未按照正常的程序、条款和条件的贷款？ | D9: √
A10: 6 | B10: 您是否与委托人或相关当事方的董事、监事、高级管理人员或者其他可能对评估施加重大影响的特定人员有近亲关系？ | D10: √
A11: 7 | B11: 您及您亲属是否存在在委托人或相关当事方担任董事、监事、高级管理人员或者其他可能对评估施加重大影响的特定职务？ | D11: √
A12: 8 | B12: 您及您亲属是否曾在委托人或者相关当事方担任主要职务（如：董事、监事、经理、主管、财务负责人等），离任后未满两年？ | D12: √
A13: 9 | B13: 您及您亲属是否存在为委托人或者相关当事人编制属于该项业务对象的数据或其他记录？ | D13: √
A14: 10 | B14: 您及您亲属是否与委托人或者相关当事方或其控股股东、董事、高级管理人员共同开办企业？ | D14: √
A15: 11 | B15: 您及您亲属是否从委托人或者相关当事方购买商品或服务，且未按照正常的商品程序交易？ | D15: √
A16: 12 | B16: 您及您亲属是否接受委托人或者相关当事方的款待超出业务活动中的正常往来或款待？ | D16: √
A17: 13 | B17: 您及您亲属是否向委托人或者相关当事人收取除业务费以外的其他费用？ | D17: √
... A21: 17 | B21: 评估专业人员是否有兼营或兼任与其执行的评估或其他鉴证业务不相容的其他业务或职务的情形？ | D21: √
A22: 18 | B22: 当您在执行评估或其他鉴证业务时遇到可能损害独立性的情形时，是否主动向本公司声明并申请回避？ | C22: √
B24: 资产评估专业人员（签名）：
B26: 项目组其他成员（签名）： | C26: 日期： | E26: =[1]基本信息!D16 -> 44259
