Workbook

Sheet basic
A1: 基本信息 | B1: 报告编号 | C1: 2021-Z0010 | D1: 合同指令号 | E1: 123
B2: 评估基准日 | C2: 2021/4/31
B3: 评估报告日 | C3: 44317
B4: 评估对象 | C4: 股东全部权益
B5: 评估范围 | C5: 全部资产和全部负债
B6: 价值类型 | C6: 市场价值
B7: 委托人 | C7: 上海A公司
B8: 被评估单位 | C8: 上海B公司
B9: 评估目的 | C9: 股权转让
B10: 打开评估长期投资 | C10: 5
A11: 综合进度 | B11: 项目 | C11: 责任人 | D11: 时间安排
B12: 基本情况调查 | C12: 小包 | D12: 44256
B13: 风险判断 | C13: 小包 | D13: 44257
B14: 委托合同签订 | C14: 小包 | D14: 44258
B15: 评估计划 | C15: 小包 | D15: 44259
B16: 前期准备 | C16: 小包 | D16: 44260 | E16: 44261
B17: 现场勘查 | C17: 小包 | D17: 44260 | E17: 44261
B18: 收集评估资料 | C18: 小包 | D18: 44260 | E18: 44261
B19: 评定估算 | C19: 小包 | D19: 44260 | E19: 44261
B20: 编制报告 | C20: 小包 | D20: 44260 | E20: 44261
B21: 内部审核 | C21: 小包 | D21: 44260 | E21: 44261
B22: 初稿 | C22: 小包 | D22: 44262
B23: 评估报告日 | C23: 小包 | D23: 44263
B24: 提交报告 | C24: 小包 | D24: 44264 | E24: 44265
B25: 报告签收 | C25: 小包 | D25: 44266
B26: 工作底稿归档 | C26: 小包 | D26: 44267 | E26: 44268
A27: 评估人员安排 | B27: 签字评估师1 | C27: 小包
B28: 签字评估师2 | C28: 小张
B29: 流动资产及负债 | C29: 小张
B30: 长期投资 | C30: 小张
B31: 房地产 | C31: 小张
B32: 机器设备 | C32: 小张
B33: 其他无形资产 | C33: 小张
B34: 整体收益法 | C34: 小张
B35: 整体市场法 | C35: 小张
A36: 收费情况 | B36: 约定收费： | C36: 10 | D36: 万元
B37: 实际收费： | C37: 10 | D37: 万元
A38: 委托人 | B38: 联系人 | C38: 小王 | D38: 电话 | E38: 6462222
A39: 被评估单位 | B39: 注册资金 | C39: 500 | D39: 地址 | E39: 天目中路88888
B40: 法定代表人 | C40: 小巧 | D40: 企业性质 | E40: 国有
...

Sheet G-1
A3: 评估业务基本事项调查表
G4: 索引号：G-1
A5: 项目名称 | C5: =[1]基本信息!F6 -> 0
A6: 委托人 | C6: =[1]基本信息!B8 -> 委托人 | D6: 联系人 | E6: =[1]基本信息!B39 -> 联系人 | F6: 电话 | G6: =[1]基本信息!D39 -> 电话
A7: 被评估单位 | B7: 名称 | C7: =[1]基本信息!B9 -> 被评估单位 | D7: 地址 | E7: =[1]基本信息!D40 -> 地址
B8: 法定代表人 | C8: =[1]基本信息!B41 -> 法定代表人 | D8: 企业性质 | E8: =[1]基本信息!D41 -> 企业性质
B9: 注册资金 | C9: =[1]基本信息!B40 -> 注册资金 | D9: 联系人 | E9: =[1]基本信息!B42 -> 联系人 | F9: 电话 | G9: =[1]基本信息!D42 -> 电话
B10: 经营范围 | C10: =[1]基本信息!B43 -> 经营范围
A11: 其他报告使用人 | C11: =[1]基本信息!A44 -> 其他报告使用人
A12: 委托人、被评估 单位、其他报告 使用人的关系 | C12: =[1]基本信息!A45 -> 委托人、被评估单位、其他报告使用人的关系
A13: 项目涉及的经济 行为的审批情况 | C13: =IF([1]基本信息!A48="是","备案或核准","")
A14: 委托人及相关当事人工作配合和协助等需要明确的重要事项 | C14: =[1]基本信息!A46 -> 委托人及相关当事人工作配合和协助等需要明确的重要事项
A15: 评估目的 | C15: =[1]档案总览!A8 -> 评估目的：
A16: 评估对象和 评估范围 | C16: ="评估对象是"&[1]基本信息!B5&","&"评估范围是"&[1]基本信息!B6 -> 评估对象是评估对象,评估范围是评估范围
A17: 主要资产状况 | C17: 流动资产、流动负债，长期资产、长期负债
A18: 价值类型 | C18: =[1]基本信息!B7 -> 价值类型 | D18: 评估基准日 | E18: =[1]档案总览!A10 -> 评估基准日：
A19: 评估假设和 限制条件 | C19: =[1]基本信息!A47 -> 评估假设和限制条件
A20: 评估报告的使用范围、提交时间和方式 | C20: 详见资产评估委托合同
A21: 评估服务费总额、 支付时间和方式 | D21: =[1]基本信息!B37 -> 约定收费： | E21: 万元
A22: 洽谈人： | D22: 审批人： | F22: 日期： | G22: =[1]基本信息!C13 -> 小包
